<?xml version='1.0'?> 
<robot name="manipulator" xmlns:xacro="http://www.ros.org/wiki/xacro">

<!--constants of the manipulator, characterstics-->
<!-- Constants for robot dimensions --> 
<xacro:property name="width" value="0.1" /> 
<xacro:property name="height1" value="2" /> 
<xacro:property name="height2" value="1" /> 
<xacro:property name="height3" value="1" />
<xacro:property name="mass1" value="10" />
<xacro:property name="mass2" value="7" />
<xacro:property name="mass3" value="5" />
<xacro:property name="mass4" value="1" />
<xacro:property name="mass5" value="0.8" />
<xacro:property name="axle_offset" value="0.05" />
<xacro:property name="damp" value="0.7" />

  <!-- Import all Gazebo-customization elements, including Gazebo colors -->
  <xacro:include filename="$(find aeriaman)/urdf/man.gazebo" />
  <!-- Import Rviz colors -->
  <!--xacro:include filename="$(find aeriaman)/urdf/materials.xacro" /-->

  <!-- Used for fixing robot to Gazebo 'base_link' -->
  <link name="world"/>

  <joint name="fixed" type="fixed">
    <parent link="world"/>
    <child link="base_link"/>
  </joint>

<!-- Base Link --> 
<link name="base_link"> 
<visual> <origin xyz="0 0 2" rpy="0 0 0" /> <geometry> <box size= "2 2 0.2" /> <material name="blue"> <color rgba="0 0 .8 1"/> </material></geometry> </visual> 
<collision> <origin xyz="0 0 2" rpy="0 0 0" /> <geometry> <box size= "2 2 0.2" /> </geometry> </collision> 
<inertial> <origin xyz="0 0 2" rpy="0 0 0" /> <mass value="${mass1}" /> <inertia ixx="${mass1 / 12.0 * (2*2 + 0.2*0.2)}" ixy="0.0" ixz="0.0"
iyy="${mass1 / 12.0 * (0.2*0.2 + 2*2)}" iyz="0.0"
izz="${mass1 / 12.0 * (2*2 + 2*2)}"/> </inertial> 

</link>

<!-- done== origin from the center of gravity-->
<!-- Joint --> 
<joint name="jf" type="fixed"> 
<parent link="base_link" /> <child link="sh_link" />
<origin xyz="0 ${width} -0.1" rpy="0 0 0" /> 
<axis xyz="0 0 0" /> <dynamics damping="${damp}" />
<limit effort="0" velocity="0" lower="0" upper="0" /> </joint>

<!-- done== origin from the last link size l1zorigin-l1zsize+l2zsize/2-->
<!-- Link --> 
<link name="sh_link"> 
<visual> <origin xyz="0 0 1.95" rpy="0 0 0" /> <geometry> <box size= "0.1 0.1 0.1" /> <material name="blue"> <color rgba="0 0 .8 1"/> </material></geometry> </visual> 
<collision> <origin xyz="0 0 1.95" rpy="0 0 0" /> <geometry> <box size= "0.1 0.1 0.1" /> </geometry> </collision> 
<inertial> <origin xyz="0 0 1.95" rpy="0 0 0" /> <mass value="${mass2}" /> 
<inertia ixx="${mass2 / 12.0 * (0.1*0.1 + 0.1*0.1)}" ixy="0.0" ixz="0.0"
iyy="${mass2 / 12.0 * (0.1*0.1 + 0.1*0.1)}" iyz="0.0"
izz="${mass2 / 12.0 * (0.1*0.1 + 0.1*0.1)}"/> </inertial> 
</link>

<!-- Joint --> 
<joint name="j1" type="revolute"> 
<parent link="sh_link" /> <child link="arm_shlink" />
<origin xyz="0 0 1.9" rpy="0 0 0" />
<axis xyz="0 1 0"/> <dynamics damping="${damp}" />
<limit effort="1000.0" velocity="0.5" lower="-1.5" upper="1.5" /> 
</joint>

<!-- Link --> 
<link name="arm_shlink"> 
<visual> <origin xyz="0 0 -0.1" rpy="0 0 0" /> <geometry> <box size= "0.1 0.1 0.2" /> <material name="blue"> <color rgba="0 0 .8 1"/> </material></geometry> </visual> 
<collision> <origin xyz="0 0 -0.1" rpy="0 0 0" /> <geometry> <box size= "0.1 0.1 0.2" /> </geometry> </collision> 
<inertial> <origin xyz="0 0 -0.1" rpy="0 0 0" /> <mass value="${mass3}" /> <inertia
ixx="${mass3 / 12.0 * (0.1*0.1 + 0.2*0.2)}" ixy="0.0" ixz="0.0"
iyy="${mass3 / 12.0 * (0.2*0.2 + 0.1*0.1)}" iyz="0.0"
izz="${mass3 / 12.0 * (0.1*0.1 + 0.1*0.1)}"/> </inertial> 
</link>
<!-- done link== origin from the center of gravity-->

<!-- Joint --> 
<joint name="j2" type="revolute"> 
<parent link="arm_shlink" /> <child link="forearm_link" />
<origin xyz="0 0 -0.2" rpy="0 0 0" /> 
<axis xyz="1 0 0" /> <dynamics damping="${damp}" />
<limit effort="1000.0" velocity="0.5" lower="-1.5" upper="1.5" /> </joint>
<!-- done joint== origin from the last link's size-->
<!-- Link --> 
<link name="forearm_link"> 
<visual> <origin xyz="0 0 -0.5" rpy="0 0 0" /> <geometry> <box size= "0.1 0.1 1" /> <material name="blue"> <color rgba="0 0 .8 1"/> </material></geometry> </visual> 
<collision> <origin xyz="0 0 -0.5" rpy="0 0 0" /> <geometry> <box size= "0.1 0.1 1" /> </geometry> </collision> 
<inertial> <origin xyz="0 0 -0.5" rpy="0 0 0" /> <mass value="${mass4}" /> <inertia
ixx="${mass4 / 12.0 * (0.1*0.1 + 1)}" ixy="0.0" ixz="0.0"
iyy="${mass4 / 12.0 * (1 + 0.1*0.1)}" iyz="0.0"
izz="${mass4 / 12.0 * (0.1*0.1 + 0.1*0.1)}"/> </inertial> 
</link>

<!-- done link== origin from the center of gravity-->
<!-- Joint --> 
<joint name="j3" type="revolute">
<parent link="forearm_link" /> <child link="arm_link" />
<origin xyz="0 0 -1" rpy="0 0 0" />
<axis xyz="1 0 0" /> <dynamics damping="${damp}" />
<limit effort="1000.0" velocity="0.5" lower="-1.5" upper="1.5" /> </joint>
<!-- done joint== origin from the last link's size-->
<!-- Link -->
<link name="arm_link">
<visual> <origin xyz="0 0 -0.4" rpy="0 0 0" /> <geometry> <box size= "0.1 0.1 0.8" /> <material name="blue"> <color rgba="0 0 .8 1"/> </material></geometry> </visual> 
<collision> <origin xyz="0 0 -0.4" rpy="0 0 0" /> <geometry> <box size= "0.1 0.1 0.8" /> </geometry> </collision>
<inertial> <origin xyz="0 0 -0.4" rpy="0 0 0" /> <mass value="${mass5}" /> <inertia ixx="${mass5 / 12.0 * (0.1*0.1 + 0.8*0.8)}" ixy="0.0" ixz="0.0"
iyy="${mass5 / 12.0 * (0.8*0.8 + 0.1*0.1)}" iyz="0.0"
izz="${mass5 / 12.0 * (0.1*0.1 + 0.1*0.1)}"/> </inertial> 
</link>


<!-- done link== origin from the center of gravity-->
<!-- Joint --> 
<joint name="j4" type="revolute">
<parent link="arm_link" /> <child link="hand_1_link" />
<origin xyz="0 0 -0.8" rpy="0 0 0" />
<axis xyz="0 0 1" /> <dynamics damping="${damp}" />
<limit effort="1000.0" velocity="0.5" lower="-1.5" upper="1.5" /> </joint>
<!-- done joint== origin from the last link's size-->
<!-- Link -->
<link name="hand_1_link">
<visual> <origin xyz="0 0 -0.05" rpy="0 0 0" /> <geometry> <box size= "0.1 0.1 0.1" /> <material name="blue"> <color rgba="0 0 .8 1"/> </material></geometry> </visual> 
<collision> <origin xyz="0 0 -0.05" rpy="0 0 0" /> <geometry> <box size= "0.1 0.1 0.8" /> </geometry> </collision>
<inertial> <origin xyz="0 0 -0.05" rpy="0 0 0" /> <mass value="${mass5}" /> <inertia ixx="${mass5 / 12.0 * (0.1*0.1 + 0.8*0.8)}" ixy="0.0" ixz="0.0"
iyy="${mass5 / 12.0 * (0.8*0.8 + 0.1*0.1)}" iyz="0.0"
izz="${mass5 / 12.0 * (0.1*0.1 + 0.1*0.1)}"/> </inertial> 
</link>


<!-- done link== origin from the center of gravity-->
<!-- Joint --> 
<joint name="j5" type="revolute">
<parent link="hand_1_link" /> <child link="hand_2_link" />
<origin xyz="0 0 -0.1" rpy="0 0 0" />
<axis xyz="1 0 0" /> <dynamics damping="${damp}" />
<limit effort="1000.0" velocity="0.5" lower="-1.5" upper="1.5" /> </joint>
<!-- done joint== origin from the last link's size-->
<!-- Link -->
<link name="hand_2_link">
<visual> <origin xyz="0 0 -0.05" rpy="0 0 0" /> <geometry> <box size= "0.1 0.1 0.1" /> <material name="blue"> <color rgba="0 0 .8 1"/> </material></geometry> </visual> 
<collision> <origin xyz="0 0 -0.05" rpy="0 0 0" /> <geometry> <box size= "0.1 0.1 0.8" /> </geometry> </collision>
<inertial> <origin xyz="0 0 -0.05" rpy="0 0 0" /> <mass value="${mass5}" /> <inertia ixx="${mass5 / 12.0 * (0.1*0.1 + 0.8*0.8)}" ixy="0.0" ixz="0.0"
iyy="${mass5 / 12.0 * (0.8*0.8 + 0.1*0.1)}" iyz="0.0"
izz="${mass5 / 12.0 * (0.1*0.1 + 0.1*0.1)}"/> </inertial> 
</link>


<!-- done link== origin from the center of gravity-->
<!-- Joint --> 
<joint name="j6" type="revolute">
<parent link="hand_2_link" /> <child link="hand_3_link" />
<origin xyz="0 0 -0.1" rpy="0 0 0" />
<axis xyz="0 1 0" /> <dynamics damping="${damp}" />
<limit effort="1000.0" velocity="0.5" lower="-1.5" upper="1.5" /> </joint>
<!-- done joint== origin from the last link's size-->
<!-- Link -->
<link name="hand_3_link">
<visual> <origin xyz="0 0 -0.2" rpy="0 0 0" /> <geometry> <box size= "0.4 0.1 0.4" /> <material name="blue"> <color rgba="0 0 .8 1"/> </material></geometry> </visual> 
<collision> <origin xyz="0 0 -0.05" rpy="0 0 0" /> <geometry> <box size= "0.1 0.1 0.8" /> </geometry> </collision>
<inertial> <origin xyz="0 0 -0.05" rpy="0 0 0" /> <mass value="${mass5}" /> <inertia ixx="${mass5 / 12.0 * (0.1*0.1 + 0.8*0.8)}" ixy="0.0" ixz="0.0"
iyy="${mass5 / 12.0 * (0.8*0.8 + 0.1*0.1)}" iyz="0.0"
izz="${mass5 / 12.0 * (0.1*0.1 + 0.1*0.1)}"/> </inertial> 
</link>

<transmission name="t1">
    <type>transmission_interface/SimpleTransmission</type>
    <joint name="j1">
      <hardwareInterface>hardware_interface/EffortJointInterface</hardwareInterface>
    </joint>
    <actuator name="m1">
      <hardwareInterface>hardware_interface/EffortJointInterface</hardwareInterface>
      <mechanicalReduction>1</mechanicalReduction>
    </actuator>
</transmission>

<transmission name="t2">
    <type>transmission_interface/SimpleTransmission</type>
    <joint name="j2">
      <hardwareInterface>hardware_interface/EffortJointInterface</hardwareInterface>
    </joint>
    <actuator name="m2">
      <hardwareInterface>hardware_interface/EffortJointInterface</hardwareInterface>
      <mechanicalReduction>1</mechanicalReduction>
    </actuator>
</transmission>

<transmission name="t3">
    <type>transmission_interface/SimpleTransmission</type>
    <joint name="j3">
      <hardwareInterface>hardware_interface/EffortJointInterface</hardwareInterface>
    </joint>
    <actuator name="m3">
      <hardwareInterface>hardware_interface/EffortJointInterface</hardwareInterface>
      <mechanicalReduction>1</mechanicalReduction>
    </actuator>
</transmission>


</robot>
